[2024-11-15T07:03:00.364+0000] {local_task_job_runner.py:123} INFO - ::group::Pre task execution logs
[2024-11-15T07:03:00.410+0000] {taskinstance.py:2613} INFO - Dependencies all met for dep_context=non-requeueable deps ti=<TaskInstance: email_pipeline.run_result_script scheduled__2024-11-15T06:55:00+00:00 [queued]>
[2024-11-15T07:03:00.430+0000] {taskinstance.py:2613} INFO - Dependencies all met for dep_context=requeueable deps ti=<TaskInstance: email_pipeline.run_result_script scheduled__2024-11-15T06:55:00+00:00 [queued]>
[2024-11-15T07:03:00.431+0000] {taskinstance.py:2866} INFO - Starting attempt 2 of 2
[2024-11-15T07:03:00.459+0000] {taskinstance.py:2889} INFO - Executing <Task(BashOperator): run_result_script> on 2024-11-15 06:55:00+00:00
[2024-11-15T07:03:00.467+0000] {warnings.py:112} WARNING - /home/***/.local/lib/python3.12/site-packages/***/task/task_runner/standard_task_runner.py:70: DeprecationWarning: This process (pid=131) is multi-threaded, use of fork() may lead to deadlocks in the child.
  pid = os.fork()

[2024-11-15T07:03:00.469+0000] {standard_task_runner.py:72} INFO - Started process 132 to run task
[2024-11-15T07:03:00.470+0000] {standard_task_runner.py:104} INFO - Running: ['***', 'tasks', 'run', 'email_pipeline', 'run_result_script', 'scheduled__2024-11-15T06:55:00+00:00', '--job-id', '6', '--raw', '--subdir', 'DAGS_FOLDER/workflow.py', '--cfg-path', '/tmp/tmp69bk4e8q']
[2024-11-15T07:03:00.473+0000] {standard_task_runner.py:105} INFO - Job 6: Subtask run_result_script
[2024-11-15T07:03:00.574+0000] {task_command.py:467} INFO - Running <TaskInstance: email_pipeline.run_result_script scheduled__2024-11-15T06:55:00+00:00 [running]> on host 1d9b6efd6c03
[2024-11-15T07:03:00.727+0000] {taskinstance.py:3132} INFO - Exporting env vars: AIRFLOW_CTX_DAG_OWNER='***' AIRFLOW_CTX_DAG_ID='email_pipeline' AIRFLOW_CTX_TASK_ID='run_result_script' AIRFLOW_CTX_EXECUTION_DATE='2024-11-15T06:55:00+00:00' AIRFLOW_CTX_TRY_NUMBER='2' AIRFLOW_CTX_DAG_RUN_ID='scheduled__2024-11-15T06:55:00+00:00'
[2024-11-15T07:03:00.729+0000] {taskinstance.py:731} INFO - ::endgroup::
[2024-11-15T07:03:00.759+0000] {subprocess.py:78} INFO - Tmp dir root location: /tmp
[2024-11-15T07:03:00.762+0000] {subprocess.py:88} INFO - Running command: ['/usr/bin/bash', '-c', 'python /opt/***/dags/result.py']
[2024-11-15T07:03:00.781+0000] {subprocess.py:99} INFO - Output:
[2024-11-15T07:03:39.067+0000] {subprocess.py:106} INFO - Traceback (most recent call last):
[2024-11-15T07:03:39.068+0000] {subprocess.py:106} INFO -   File "/opt/***/dags/result.py", line 42, in <module>
[2024-11-15T07:03:39.071+0000] {subprocess.py:106} INFO -     if not collection.find_one({"message": row['message']}):
[2024-11-15T07:03:39.072+0000] {subprocess.py:106} INFO -            ^^^^^^^^^^^^^^^^^^^^^^^^^^^^^^^^^^^^^^^^^^^^^^^^
[2024-11-15T07:03:39.072+0000] {subprocess.py:106} INFO -   File "/home/***/.local/lib/python3.12/site-packages/pymongo/collection.py", line 1508, in find_one
[2024-11-15T07:03:39.073+0000] {subprocess.py:106} INFO -     for result in cursor.limit(-1):
[2024-11-15T07:03:39.074+0000] {subprocess.py:106} INFO -                   ^^^^^^^^^^^^^^^^
[2024-11-15T07:03:39.074+0000] {subprocess.py:106} INFO -   File "/home/***/.local/lib/python3.12/site-packages/pymongo/cursor.py", line 1262, in next
[2024-11-15T07:03:39.075+0000] {subprocess.py:106} INFO -     if len(self.__data) or self._refresh():
[2024-11-15T07:03:39.076+0000] {subprocess.py:106} INFO -                            ^^^^^^^^^^^^^^^
[2024-11-15T07:03:39.076+0000] {subprocess.py:106} INFO -   File "/home/***/.local/lib/python3.12/site-packages/pymongo/cursor.py", line 1153, in _refresh
[2024-11-15T07:03:39.077+0000] {subprocess.py:106} INFO -     self.__session = self.__collection.database.client._ensure_session()
[2024-11-15T07:03:39.077+0000] {subprocess.py:106} INFO -                      ^^^^^^^^^^^^^^^^^^^^^^^^^^^^^^^^^^^^^^^^^^^^^^^^^^^
[2024-11-15T07:03:39.078+0000] {subprocess.py:106} INFO -   File "/home/***/.local/lib/python3.12/site-packages/pymongo/mongo_client.py", line 1868, in _ensure_session
[2024-11-15T07:03:39.079+0000] {subprocess.py:106} INFO -     return self.__start_session(True, causal_consistency=False)
[2024-11-15T07:03:39.079+0000] {subprocess.py:106} INFO -            ^^^^^^^^^^^^^^^^^^^^^^^^^^^^^^^^^^^^^^^^^^^^^^^^^^^^
[2024-11-15T07:03:39.080+0000] {subprocess.py:106} INFO -   File "/home/***/.local/lib/python3.12/site-packages/pymongo/mongo_client.py", line 1811, in __start_session
[2024-11-15T07:03:39.080+0000] {subprocess.py:106} INFO -     self._topology._check_implicit_session_support()
[2024-11-15T07:03:39.081+0000] {subprocess.py:106} INFO -   File "/home/***/.local/lib/python3.12/site-packages/pymongo/topology.py", line 583, in _check_implicit_session_support
[2024-11-15T07:03:39.081+0000] {subprocess.py:106} INFO -     self._check_session_support()
[2024-11-15T07:03:39.082+0000] {subprocess.py:106} INFO -   File "/home/***/.local/lib/python3.12/site-packages/pymongo/topology.py", line 599, in _check_session_support
[2024-11-15T07:03:39.084+0000] {subprocess.py:106} INFO -     self._select_servers_loop(
[2024-11-15T07:03:39.084+0000] {subprocess.py:106} INFO -   File "/home/***/.local/lib/python3.12/site-packages/pymongo/topology.py", line 269, in _select_servers_loop
[2024-11-15T07:03:39.086+0000] {subprocess.py:106} INFO -     raise ServerSelectionTimeoutError(
[2024-11-15T07:03:39.087+0000] {subprocess.py:106} INFO - pymongo.errors.ServerSelectionTimeoutError: mongodb:27017: [Errno -5] No address associated with hostname, Timeout: 30s, Topology Description: <TopologyDescription id: 6736f227a52515e62355cd7a, topology_type: Unknown, servers: [<ServerDescription ('mongodb', 27017) server_type: Unknown, rtt: None, error=AutoReconnect('mongodb:27017: [Errno -5] No address associated with hostname')>]>
[2024-11-15T07:03:40.346+0000] {subprocess.py:110} INFO - Command exited with return code 1
[2024-11-15T07:03:40.376+0000] {taskinstance.py:3311} ERROR - Task failed with exception
Traceback (most recent call last):
  File "/home/airflow/.local/lib/python3.12/site-packages/airflow/models/taskinstance.py", line 767, in _execute_task
    result = _execute_callable(context=context, **execute_callable_kwargs)
             ^^^^^^^^^^^^^^^^^^^^^^^^^^^^^^^^^^^^^^^^^^^^^^^^^^^^^^^^^^^^^
  File "/home/airflow/.local/lib/python3.12/site-packages/airflow/models/taskinstance.py", line 733, in _execute_callable
    return ExecutionCallableRunner(
           ^^^^^^^^^^^^^^^^^^^^^^^^
  File "/home/airflow/.local/lib/python3.12/site-packages/airflow/utils/operator_helpers.py", line 252, in run
    return self.func(*args, **kwargs)
           ^^^^^^^^^^^^^^^^^^^^^^^^^^
  File "/home/airflow/.local/lib/python3.12/site-packages/airflow/models/baseoperator.py", line 417, in wrapper
    return func(self, *args, **kwargs)
           ^^^^^^^^^^^^^^^^^^^^^^^^^^^
  File "/home/airflow/.local/lib/python3.12/site-packages/airflow/operators/bash.py", line 276, in execute
    raise AirflowException(
airflow.exceptions.AirflowException: Bash command failed. The command returned a non-zero exit code 1.
[2024-11-15T07:03:40.382+0000] {taskinstance.py:1225} INFO - Marking task as FAILED. dag_id=email_pipeline, task_id=run_result_script, run_id=scheduled__2024-11-15T06:55:00+00:00, execution_date=20241115T065500, start_date=20241115T070300, end_date=20241115T070340
[2024-11-15T07:03:40.410+0000] {taskinstance.py:340} INFO - ::group::Post task execution logs
[2024-11-15T07:03:40.411+0000] {standard_task_runner.py:124} ERROR - Failed to execute job 6 for task run_result_script (Bash command failed. The command returned a non-zero exit code 1.; 132)
Traceback (most recent call last):
  File "/home/airflow/.local/lib/python3.12/site-packages/airflow/task/task_runner/standard_task_runner.py", line 117, in _start_by_fork
    ret = args.func(args, dag=self.dag)
          ^^^^^^^^^^^^^^^^^^^^^^^^^^^^^
  File "/home/airflow/.local/lib/python3.12/site-packages/airflow/cli/cli_config.py", line 49, in command
    return func(*args, **kwargs)
           ^^^^^^^^^^^^^^^^^^^^^
  File "/home/airflow/.local/lib/python3.12/site-packages/airflow/utils/cli.py", line 116, in wrapper
    return f(*args, **kwargs)
           ^^^^^^^^^^^^^^^^^^
  File "/home/airflow/.local/lib/python3.12/site-packages/airflow/cli/commands/task_command.py", line 483, in task_run
    task_return_code = _run_task_by_selected_method(args, _dag, ti)
                       ^^^^^^^^^^^^^^^^^^^^^^^^^^^^^^^^^^^^^^^^^^^^
  File "/home/airflow/.local/lib/python3.12/site-packages/airflow/cli/commands/task_command.py", line 256, in _run_task_by_selected_method
    return _run_raw_task(args, ti)
           ^^^^^^^^^^^^^^^^^^^^^^^
  File "/home/airflow/.local/lib/python3.12/site-packages/airflow/cli/commands/task_command.py", line 341, in _run_raw_task
    return ti._run_raw_task(
           ^^^^^^^^^^^^^^^^^
  File "/home/airflow/.local/lib/python3.12/site-packages/airflow/utils/session.py", line 97, in wrapper
    return func(*args, session=session, **kwargs)
           ^^^^^^^^^^^^^^^^^^^^^^^^^^^^^^^^^^^^^^
  File "/home/airflow/.local/lib/python3.12/site-packages/airflow/models/taskinstance.py", line 3005, in _run_raw_task
    return _run_raw_task(
           ^^^^^^^^^^^^^^
  File "/home/airflow/.local/lib/python3.12/site-packages/airflow/models/taskinstance.py", line 273, in _run_raw_task
    TaskInstance._execute_task_with_callbacks(
  File "/home/airflow/.local/lib/python3.12/site-packages/airflow/models/taskinstance.py", line 3159, in _execute_task_with_callbacks
    result = self._execute_task(context, task_orig)
             ^^^^^^^^^^^^^^^^^^^^^^^^^^^^^^^^^^^^^^
  File "/home/airflow/.local/lib/python3.12/site-packages/airflow/models/taskinstance.py", line 3183, in _execute_task
    return _execute_task(self, context, task_orig)
           ^^^^^^^^^^^^^^^^^^^^^^^^^^^^^^^^^^^^^^^
  File "/home/airflow/.local/lib/python3.12/site-packages/airflow/models/taskinstance.py", line 767, in _execute_task
    result = _execute_callable(context=context, **execute_callable_kwargs)
             ^^^^^^^^^^^^^^^^^^^^^^^^^^^^^^^^^^^^^^^^^^^^^^^^^^^^^^^^^^^^^
  File "/home/airflow/.local/lib/python3.12/site-packages/airflow/models/taskinstance.py", line 733, in _execute_callable
    return ExecutionCallableRunner(
           ^^^^^^^^^^^^^^^^^^^^^^^^
  File "/home/airflow/.local/lib/python3.12/site-packages/airflow/utils/operator_helpers.py", line 252, in run
    return self.func(*args, **kwargs)
           ^^^^^^^^^^^^^^^^^^^^^^^^^^
  File "/home/airflow/.local/lib/python3.12/site-packages/airflow/models/baseoperator.py", line 417, in wrapper
    return func(self, *args, **kwargs)
           ^^^^^^^^^^^^^^^^^^^^^^^^^^^
  File "/home/airflow/.local/lib/python3.12/site-packages/airflow/operators/bash.py", line 276, in execute
    raise AirflowException(
airflow.exceptions.AirflowException: Bash command failed. The command returned a non-zero exit code 1.
[2024-11-15T07:03:40.441+0000] {local_task_job_runner.py:266} INFO - Task exited with return code 1
[2024-11-15T07:03:40.462+0000] {taskinstance.py:3895} INFO - 0 downstream tasks scheduled from follow-on schedule check
[2024-11-15T07:03:40.467+0000] {local_task_job_runner.py:245} INFO - ::endgroup::
[2024-11-15T07:03:40.479+0000] {standard_task_runner.py:217} INFO - Process not found (most likely exited), stop collecting metrics
