[2024-11-15T07:05:01.735+0000] {local_task_job_runner.py:123} INFO - ::group::Pre task execution logs
[2024-11-15T07:05:01.762+0000] {taskinstance.py:2613} INFO - Dependencies all met for dep_context=non-requeueable deps ti=<TaskInstance: email_pipeline.run_result_script scheduled__2024-11-15T07:00:00+00:00 [queued]>
[2024-11-15T07:05:01.779+0000] {taskinstance.py:2613} INFO - Dependencies all met for dep_context=requeueable deps ti=<TaskInstance: email_pipeline.run_result_script scheduled__2024-11-15T07:00:00+00:00 [queued]>
[2024-11-15T07:05:01.780+0000] {taskinstance.py:2866} INFO - Starting attempt 1 of 2
[2024-11-15T07:05:01.807+0000] {taskinstance.py:2889} INFO - Executing <Task(BashOperator): run_result_script> on 2024-11-15 07:00:00+00:00
[2024-11-15T07:05:01.813+0000] {warnings.py:112} WARNING - /home/***/.local/lib/python3.12/site-packages/***/task/task_runner/standard_task_runner.py:70: DeprecationWarning: This process (pid=175) is multi-threaded, use of fork() may lead to deadlocks in the child.
  pid = os.fork()

[2024-11-15T07:05:01.815+0000] {standard_task_runner.py:72} INFO - Started process 176 to run task
[2024-11-15T07:05:01.815+0000] {standard_task_runner.py:104} INFO - Running: ['***', 'tasks', 'run', 'email_pipeline', 'run_result_script', 'scheduled__2024-11-15T07:00:00+00:00', '--job-id', '7', '--raw', '--subdir', 'DAGS_FOLDER/workflow.py', '--cfg-path', '/tmp/tmpdpl_b4dr']
[2024-11-15T07:05:01.817+0000] {standard_task_runner.py:105} INFO - Job 7: Subtask run_result_script
[2024-11-15T07:05:01.881+0000] {task_command.py:467} INFO - Running <TaskInstance: email_pipeline.run_result_script scheduled__2024-11-15T07:00:00+00:00 [running]> on host 1d9b6efd6c03
[2024-11-15T07:05:01.992+0000] {taskinstance.py:3132} INFO - Exporting env vars: AIRFLOW_CTX_DAG_OWNER='***' AIRFLOW_CTX_DAG_ID='email_pipeline' AIRFLOW_CTX_TASK_ID='run_result_script' AIRFLOW_CTX_EXECUTION_DATE='2024-11-15T07:00:00+00:00' AIRFLOW_CTX_TRY_NUMBER='1' AIRFLOW_CTX_DAG_RUN_ID='scheduled__2024-11-15T07:00:00+00:00'
[2024-11-15T07:05:01.994+0000] {taskinstance.py:731} INFO - ::endgroup::
[2024-11-15T07:05:02.019+0000] {subprocess.py:78} INFO - Tmp dir root location: /tmp
[2024-11-15T07:05:02.021+0000] {subprocess.py:88} INFO - Running command: ['/usr/bin/bash', '-c', 'python /opt/***/dags/result.py']
[2024-11-15T07:05:02.031+0000] {subprocess.py:99} INFO - Output:
[2024-11-15T07:05:41.013+0000] {subprocess.py:106} INFO - Traceback (most recent call last):
[2024-11-15T07:05:41.015+0000] {subprocess.py:106} INFO -   File "/opt/***/dags/result.py", line 42, in <module>
[2024-11-15T07:05:41.018+0000] {subprocess.py:106} INFO -     new_records.append({"file": row['file'], "message": row['message']})
[2024-11-15T07:05:41.021+0000] {subprocess.py:106} INFO -        ^^^^^^^^^^^^^^^^^^^^^^^^^^^^^^^^^^^^^^^^^^^^^^^^
[2024-11-15T07:05:41.022+0000] {subprocess.py:106} INFO -   File "/home/***/.local/lib/python3.12/site-packages/pymongo/collection.py", line 1508, in find_one
[2024-11-15T07:05:41.023+0000] {subprocess.py:106} INFO -     for result in cursor.limit(-1):
[2024-11-15T07:05:41.023+0000] {subprocess.py:106} INFO -                   ^^^^^^^^^^^^^^^^
[2024-11-15T07:05:41.024+0000] {subprocess.py:106} INFO -   File "/home/***/.local/lib/python3.12/site-packages/pymongo/cursor.py", line 1262, in next
[2024-11-15T07:05:41.024+0000] {subprocess.py:106} INFO -     if len(self.__data) or self._refresh():
[2024-11-15T07:05:41.025+0000] {subprocess.py:106} INFO -                            ^^^^^^^^^^^^^^^
[2024-11-15T07:05:41.025+0000] {subprocess.py:106} INFO -   File "/home/***/.local/lib/python3.12/site-packages/pymongo/cursor.py", line 1153, in _refresh
[2024-11-15T07:05:41.026+0000] {subprocess.py:106} INFO -     self.__session = self.__collection.database.client._ensure_session()
[2024-11-15T07:05:41.026+0000] {subprocess.py:106} INFO -                      ^^^^^^^^^^^^^^^^^^^^^^^^^^^^^^^^^^^^^^^^^^^^^^^^^^^
[2024-11-15T07:05:41.026+0000] {subprocess.py:106} INFO -   File "/home/***/.local/lib/python3.12/site-packages/pymongo/mongo_client.py", line 1868, in _ensure_session
[2024-11-15T07:05:41.027+0000] {subprocess.py:106} INFO -     return self.__start_session(True, causal_consistency=False)
[2024-11-15T07:05:41.027+0000] {subprocess.py:106} INFO -            ^^^^^^^^^^^^^^^^^^^^^^^^^^^^^^^^^^^^^^^^^^^^^^^^^^^^
[2024-11-15T07:05:41.027+0000] {subprocess.py:106} INFO -   File "/home/***/.local/lib/python3.12/site-packages/pymongo/mongo_client.py", line 1811, in __start_session
[2024-11-15T07:05:41.028+0000] {subprocess.py:106} INFO -     self._topology._check_implicit_session_support()
[2024-11-15T07:05:41.028+0000] {subprocess.py:106} INFO -   File "/home/***/.local/lib/python3.12/site-packages/pymongo/topology.py", line 583, in _check_implicit_session_support
[2024-11-15T07:05:41.028+0000] {subprocess.py:106} INFO -     self._check_session_support()
[2024-11-15T07:05:41.029+0000] {subprocess.py:106} INFO -   File "/home/***/.local/lib/python3.12/site-packages/pymongo/topology.py", line 599, in _check_session_support
[2024-11-15T07:05:41.029+0000] {subprocess.py:106} INFO -     self._select_servers_loop(
[2024-11-15T07:05:41.029+0000] {subprocess.py:106} INFO -   File "/home/***/.local/lib/python3.12/site-packages/pymongo/topology.py", line 269, in _select_servers_loop
[2024-11-15T07:05:41.030+0000] {subprocess.py:106} INFO -     raise ServerSelectionTimeoutError(
[2024-11-15T07:05:41.030+0000] {subprocess.py:106} INFO - pymongo.errors.ServerSelectionTimeoutError: mongodb:27017: [Errno -5] No address associated with hostname, Timeout: 30s, Topology Description: <TopologyDescription id: 6736f2a08fcc3094c818be4e, topology_type: Unknown, servers: [<ServerDescription ('mongodb', 27017) server_type: Unknown, rtt: None, error=AutoReconnect('mongodb:27017: [Errno -5] No address associated with hostname')>]>
[2024-11-15T07:05:42.226+0000] {subprocess.py:110} INFO - Command exited with return code 1
[2024-11-15T07:05:42.240+0000] {taskinstance.py:3311} ERROR - Task failed with exception
Traceback (most recent call last):
  File "/home/airflow/.local/lib/python3.12/site-packages/airflow/models/taskinstance.py", line 767, in _execute_task
    result = _execute_callable(context=context, **execute_callable_kwargs)
             ^^^^^^^^^^^^^^^^^^^^^^^^^^^^^^^^^^^^^^^^^^^^^^^^^^^^^^^^^^^^^
  File "/home/airflow/.local/lib/python3.12/site-packages/airflow/models/taskinstance.py", line 733, in _execute_callable
    return ExecutionCallableRunner(
           ^^^^^^^^^^^^^^^^^^^^^^^^
  File "/home/airflow/.local/lib/python3.12/site-packages/airflow/utils/operator_helpers.py", line 252, in run
    return self.func(*args, **kwargs)
           ^^^^^^^^^^^^^^^^^^^^^^^^^^
  File "/home/airflow/.local/lib/python3.12/site-packages/airflow/models/baseoperator.py", line 417, in wrapper
    return func(self, *args, **kwargs)
           ^^^^^^^^^^^^^^^^^^^^^^^^^^^
  File "/home/airflow/.local/lib/python3.12/site-packages/airflow/operators/bash.py", line 276, in execute
    raise AirflowException(
airflow.exceptions.AirflowException: Bash command failed. The command returned a non-zero exit code 1.
[2024-11-15T07:05:42.252+0000] {taskinstance.py:1225} INFO - Marking task as UP_FOR_RETRY. dag_id=email_pipeline, task_id=run_result_script, run_id=scheduled__2024-11-15T07:00:00+00:00, execution_date=20241115T070000, start_date=20241115T070501, end_date=20241115T070542
[2024-11-15T07:05:42.279+0000] {taskinstance.py:340} INFO - ::group::Post task execution logs
[2024-11-15T07:05:42.280+0000] {standard_task_runner.py:124} ERROR - Failed to execute job 7 for task run_result_script (Bash command failed. The command returned a non-zero exit code 1.; 176)
Traceback (most recent call last):
  File "/home/airflow/.local/lib/python3.12/site-packages/airflow/task/task_runner/standard_task_runner.py", line 117, in _start_by_fork
    ret = args.func(args, dag=self.dag)
          ^^^^^^^^^^^^^^^^^^^^^^^^^^^^^
  File "/home/airflow/.local/lib/python3.12/site-packages/airflow/cli/cli_config.py", line 49, in command
    return func(*args, **kwargs)
           ^^^^^^^^^^^^^^^^^^^^^
  File "/home/airflow/.local/lib/python3.12/site-packages/airflow/utils/cli.py", line 116, in wrapper
    return f(*args, **kwargs)
           ^^^^^^^^^^^^^^^^^^
  File "/home/airflow/.local/lib/python3.12/site-packages/airflow/cli/commands/task_command.py", line 483, in task_run
    task_return_code = _run_task_by_selected_method(args, _dag, ti)
                       ^^^^^^^^^^^^^^^^^^^^^^^^^^^^^^^^^^^^^^^^^^^^
  File "/home/airflow/.local/lib/python3.12/site-packages/airflow/cli/commands/task_command.py", line 256, in _run_task_by_selected_method
    return _run_raw_task(args, ti)
           ^^^^^^^^^^^^^^^^^^^^^^^
  File "/home/airflow/.local/lib/python3.12/site-packages/airflow/cli/commands/task_command.py", line 341, in _run_raw_task
    return ti._run_raw_task(
           ^^^^^^^^^^^^^^^^^
  File "/home/airflow/.local/lib/python3.12/site-packages/airflow/utils/session.py", line 97, in wrapper
    return func(*args, session=session, **kwargs)
           ^^^^^^^^^^^^^^^^^^^^^^^^^^^^^^^^^^^^^^
  File "/home/airflow/.local/lib/python3.12/site-packages/airflow/models/taskinstance.py", line 3005, in _run_raw_task
    return _run_raw_task(
           ^^^^^^^^^^^^^^
  File "/home/airflow/.local/lib/python3.12/site-packages/airflow/models/taskinstance.py", line 273, in _run_raw_task
    TaskInstance._execute_task_with_callbacks(
  File "/home/airflow/.local/lib/python3.12/site-packages/airflow/models/taskinstance.py", line 3159, in _execute_task_with_callbacks
    result = self._execute_task(context, task_orig)
             ^^^^^^^^^^^^^^^^^^^^^^^^^^^^^^^^^^^^^^
  File "/home/airflow/.local/lib/python3.12/site-packages/airflow/models/taskinstance.py", line 3183, in _execute_task
    return _execute_task(self, context, task_orig)
           ^^^^^^^^^^^^^^^^^^^^^^^^^^^^^^^^^^^^^^^
  File "/home/airflow/.local/lib/python3.12/site-packages/airflow/models/taskinstance.py", line 767, in _execute_task
    result = _execute_callable(context=context, **execute_callable_kwargs)
             ^^^^^^^^^^^^^^^^^^^^^^^^^^^^^^^^^^^^^^^^^^^^^^^^^^^^^^^^^^^^^
  File "/home/airflow/.local/lib/python3.12/site-packages/airflow/models/taskinstance.py", line 733, in _execute_callable
    return ExecutionCallableRunner(
           ^^^^^^^^^^^^^^^^^^^^^^^^
  File "/home/airflow/.local/lib/python3.12/site-packages/airflow/utils/operator_helpers.py", line 252, in run
    return self.func(*args, **kwargs)
           ^^^^^^^^^^^^^^^^^^^^^^^^^^
  File "/home/airflow/.local/lib/python3.12/site-packages/airflow/models/baseoperator.py", line 417, in wrapper
    return func(self, *args, **kwargs)
           ^^^^^^^^^^^^^^^^^^^^^^^^^^^
  File "/home/airflow/.local/lib/python3.12/site-packages/airflow/operators/bash.py", line 276, in execute
    raise AirflowException(
airflow.exceptions.AirflowException: Bash command failed. The command returned a non-zero exit code 1.
[2024-11-15T07:05:42.306+0000] {local_task_job_runner.py:266} INFO - Task exited with return code 1
[2024-11-15T07:05:42.328+0000] {taskinstance.py:3895} INFO - 0 downstream tasks scheduled from follow-on schedule check
[2024-11-15T07:05:42.333+0000] {local_task_job_runner.py:245} INFO - ::endgroup::
